<?xml version="1.0"?>
<robot name="boat">
  <link name="base_link">
    <inertial>
      <origin xyz="0 0 0.124229" rpy="0 0 0"/>
      <mass value="227"/>
      <inertia ixx="181.42" ixy="0" ixz="0" iyy="408.203" iyz="0" izz="495.037"/>
    </inertial>
    <collision name="left_float">
      <origin xyz="-0.4 1.03 0.2" rpy="3.14159 1.57079 3.14159"/>
      <geometry>
        <cylinder length="4" radius="0.2"/>
      </geometry>
    </collision>
    <collision name="left_mid_float">
      <origin xyz="1.85 1.03 0.3" rpy="0 1.38 0"/>
      <geometry>
        <cylinder length="0.5" radius="0.17"/>
      </geometry>
    </collision>
    <collision name="left_front_float">
      <origin xyz="2.3 1.03 0.4" rpy="0 1.3 0"/>
      <geometry>
        <cylinder length="0.45" radius="0.12"/>
      </geometry>
    </collision>
    <collision name="front_left_beam_lower">
      <origin xyz="0.9 0.85 1" rpy="0.78 0 0"/>
      <geometry>
        <cylinder length="0.5" radius="0.04"/>
      </geometry>
    </collision>
    <collision name="front_left_beam_upper">
      <origin xyz="0.9 0.6 1.18" rpy="1.35 0 0"/>
      <geometry>
        <cylinder length="0.2" radius="0.04"/>
      </geometry>
    </collision>
    <collision name="mid_left_beam_lower">
      <origin xyz="-0.65 0.99 0.7" rpy="0.1 0.25 0"/>
      <geometry>
        <cylinder length="0.45" radius="0.03"/>
      </geometry>
    </collision>
    <collision name="mid_left_beam_medium">
      <origin xyz="-0.57 0.87 1.05" rpy="0.75 0.25 0"/>
      <geometry>
        <cylinder length="0.32" radius="0.03"/>
      </geometry>
    </collision>
    <collision name="mid_left_beam_upper">
      <origin xyz="-0.55 0.65 1.17" rpy="1.35 0.25 0"/>
      <geometry>
        <cylinder length="0.3" radius="0.03"/>
      </geometry>
    </collision>
    <collision name="rear_left_beam_lower">
      <origin xyz="-0.74 1.03 0.7" rpy="0 -0.15 0"/>
      <geometry>
        <cylinder length="0.45" radius="0.03"/>
      </geometry>
    </collision>
    <collision name="rear_left_beam_medium">
      <origin xyz="-0.79 0.91 1.05" rpy="0.75 -0.15 0"/>
      <geometry>
        <cylinder length="0.32" radius="0.03"/>
      </geometry>
    </collision>
    <collision name="rear_left_beam_upper">
      <origin xyz="-0.81 0.67 1.18" rpy="1.45 -0.15 0"/>
      <geometry>
        <cylinder length="0.3" radius="0.03"/>
      </geometry>
    </collision>
    <collision name="left_joint_collision">
      <origin xyz="0.58 1.03 0.6" rpy="0 -0.6 0"/>
      <geometry>
        <box size="0.65 0.2 0.1"/>
      </geometry>
    </collision>
    <collision name="right_float">
      <origin xyz="-0.4 -1.03 0.2" rpy="3.14159 1.57079 3.14159"/>
      <geometry>
        <cylinder length="4" radius="0.2"/>
      </geometry>
    </collision>
    <collision name="right_mid_float">
      <origin xyz="1.85 -1.03 0.3" rpy="0 1.38 0"/>
      <geometry>
        <cylinder length="0.5" radius="0.17"/>
      </geometry>
    </collision>
    <collision name="right_front_float">
      <origin xyz="2.3 -1.03 0.4" rpy="0 1.3 0"/>
      <geometry>
        <cylinder length="0.45" radius="0.12"/>
      </geometry>
    </collision>
    <collision name="front_right_beam_lower">
      <origin xyz="0.9 -0.85 1" rpy="-0.78 0 0"/>
      <geometry>
        <cylinder length="0.5" radius="0.04"/>
      </geometry>
    </collision>
    <collision name="front_right_beam_upper">
      <origin xyz="0.9 -0.6 1.18" rpy="-1.35 0 0"/>
      <geometry>
        <cylinder length="0.2" radius="0.04"/>
      </geometry>
    </collision>
    <collision name="mid_right_beam_lower">
      <origin xyz="-0.65 -0.99 0.7" rpy="-0.1 0.25 0"/>
      <geometry>
        <cylinder length="0.45" radius="0.03"/>
      </geometry>
    </collision>
    <collision name="mid_right_beam_medium">
      <origin xyz="-0.57 -0.87 1.05" rpy="-0.75 0.25 0"/>
      <geometry>
        <cylinder length="0.32" radius="0.03"/>
      </geometry>
    </collision>
    <collision name="mid_right_beam_upper">
      <origin xyz="-0.55 -0.65 1.17" rpy="-1.35 0.25 0"/>
      <geometry>
        <cylinder length="0.3" radius="0.03"/>
      </geometry>
    </collision>
    <collision name="rear_right_beam_lower">
      <origin xyz="-0.74 -1.03 0.7" rpy="0 -0.15 0"/>
      <geometry>
        <cylinder length="0.45" radius="0.03"/>
      </geometry>
    </collision>
    <collision name="rear_right_beam_medium">
      <origin xyz="-0.79 -0.91 1.05" rpy="-0.75 -0.15 0"/>
      <geometry>
        <cylinder length="0.32" radius="0.03"/>
      </geometry>
    </collision>
    <collision name="rear_right_beam_upper">
      <origin xyz="-0.81 -0.67 1.18" rpy="-1.45 -0.15 0"/>
      <geometry>
        <cylinder length="0.3" radius="0.03"/>
      </geometry>
    </collision>
    <collision name="right_joint_collision">
      <origin xyz="0.58 -1.03 0.6" rpy="0 -0.6 0"/>
      <geometry>
        <box size="0.65 0.2 0.1"/>
      </geometry>
    </collision>
    <collision name="top_base_collision">
      <origin xyz="0 0 1.25" rpy="0 0 0"/>
      <geometry>
        <box size="1.85 1 0.1"/>
      </geometry>
    </collision>
 
    <visual name="base_link_visual">
      <origin xyz="0 0 0" rpy="0 0 0"/>
      <geometry>
        <mesh filename="model://boat/meshes/body.dae" scale="1 1 1"/>
      </geometry>
    </visual>

    <visual name="right_engine_visual">
      <origin xyz="-2.37378 -1.02713 0.318237" rpy="0 0 0"/>
      <geometry>
        <mesh filename="model://boat/meshes/engine.dae" scale="1 1 1"/>
      </geometry>
    </visual>

    <visual name="left_engine_visual">
      <origin xyz="-2.37378 1.02713 0.318237" rpy="0 0 0"/>
      <geometry>
        <mesh filename="model://boat/meshes/engine.dae" scale="1 1 1"/>
      </geometry>
    </visual>
  </link>

  <link name="left_propeller_link">
    <inertial>
      <origin xyz="0 0 0" rpy="0 0 0"/>
      <mass value="0.5"/>
      <inertia ixx="0.008545" ixy="0" ixz="0" iyy="0.008545" iyz="0" izz="0.0144"/>
    </inertial>
    <visual>
      <origin xyz="0 0 0" rpy="0 0 0"/>
      <geometry>
        <mesh filename="model://boat/meshes/propeller.dae" scale="1 1 1"/>
      </geometry>
    </visual>
    <collision>
      <origin xyz="-0.08 0 0" rpy="3.14159 0 3.14159"/>
      <geometry>
        <cylinder length="0.18" radius="0.24"/>
      </geometry>
    </collision>
  </link>

  <link name="right_propeller_link">
    <inertial>
      <origin xyz="0 0 0" rpy="0 0 0"/>
      <mass value="0.5"/>
      <inertia ixx="0.008545" ixy="0" ixz="0" iyy="0.008545" iyz="0" izz="0.0144"/>
    </inertial>
    <visual>
      <origin xyz="0 0 0" rpy="0 0 0"/>
      <geometry>
        <mesh filename="model://boat/meshes/propeller.dae" scale="1 1 1"/>
      </geometry>
    </visual>
    <collision>
      <origin xyz="-0.08 0 0" rpy="3.14159 0 3.14159"/>
      <geometry>
        <cylinder length="0.18" radius="0.24"/>
      </geometry>
    </collision>
  </link>

  <joint name="left_engine_propeller_joint" type="revolute">
      <parent link="base_link"/>
      <child link="left_propeller_link"/>
      <origin xyz="-2.65193 1.02713 -0.191134" rpy="0 0 0"/>
      <axis xyz="1 0 0"/>
      <limit lower="-1000" upper="1000" effort="10" velocity="1000"/>
  </joint>

  <joint name="right_engine_propeller_joint" type="revolute">
      <parent link="base_link"/>
      <child link="right_propeller_link"/>
      <origin xyz="-2.65193 -1.02713 -0.191134" rpy="0 0 0"/>
      <axis xyz="1 0 0"/>
      <limit lower="-1000" upper="1000" effort="10" velocity="1000"/>
  </joint>

  <gazebo>
    <plugin name="usv_dynamics_boat" filename="libusv_gazebo_dynamics_plugin.so">
      <bodyName>base_link</bodyName>
      <waterLevel>0</waterLevel>
      <waterDensity>997.8</waterDensity>
      <xDotU>0.0</xDotU>
      <yDotV>0.0</yDotV>
      <nDotR>0.0</nDotR>
      <xU>51.3</xU>
      <xUU>72.4</xUU>
      <yV>40.0</yV>
      <yVV>0.0</yVV>
      <zW>500.0</zW>
      <kP>50.0</kP>
      <mQ>50.0</mQ>
      <nR>400.0</nR>
      <nRR>0.0</nRR>
      <hullRadius>0.213</hullRadius>
      <boatWidth>5</boatWidth>
      <boatLength>5</boatLength>
      <length_n>2</length_n>
      <wave_model>ocean_waves</wave_model>
    </plugin>
    <plugin name="boat_thrust_plugin" filename="libusv_gazebo_thrust_plugin.so">
      <robotNamespace>/boat</robotNamespace>
      <thruster>
        <linkName>left_propeller_link</linkName>
        <propJointName>left_engine_propeller_joint</propJointName>
        <engineJointName>left_engine_propeller_joint</engineJointName>
        <cmdTopic>/boat/thrusters/left_thrust_cmd</cmdTopic>
        <angleTopic>boat/thrusters/left_thrust_angle</angleTopic>
        <enableAngle>false</enableAngle>
        <maxForceFwd>200</maxForceFwd>
        <maxForceRev>-200</maxForceRev>
      </thruster>
      <thruster>
        <linkName>right_propeller_link</linkName>
        <propJointName>right_engine_propeller_joint</propJointName>
        <engineJointName>right_engine_propeller_joint</engineJointName>
        <cmdTopic>/boat/thrusters/right_thrust_cmd</cmdTopic>
        <angleTopic>boat/thrusters/right_thrust_angle</angleTopic>
        <enableAngle>false</enableAngle>
        <maxForceFwd>200</maxForceFwd>
        <maxForceRev>-200</maxForceRev>
      </thruster>
    </plugin>
  </gazebo>
</robot>
